Workbook
Name FUCK: #REF!
Name FUCK1: #REF!
Name FUCK2: #REF!
Name FUCK4: #REF!
Name KEVIN3: #REF!
Name MIMI: #REF!
Name MIMI1: #REF!
Name MIMI2: #REF!
Name Print_Area_MI: #REF!
Name RRRR: #REF!
Name 全店店舖: #REF!
Name 薪資明細: [1]薪資明細表!$A$3:$I$73

Sheet 行程異動連絡單
A1: 盤點行程異動聯絡單 | F1: 盤點中心 | H1: 盤點中心
F3: 經(副)理 | H3: 課 長
A4: 1
A5: 店 號 | B5: 店 名 | C5: 網路電話 | D5: 原訂日程 | F5: 異動原由 | H5: 通知人員 | I5: 確認人
A6: 023308 | B6: =IF(A6="","",LEFT(INDEX(店舖!$A:$L,MATCH(A6,店舖!$B:$B,),MATCH("店名",店舖!$1:$1,)),5)) -> 汐止新樹店 | C6: =IF(B6="","",LEFT(INDEX(店舖!$A:$L,MATCH(A6,店舖!$B:$B,),MATCH("電話",店舖!$1:$1,)),10)) -> 02-7753227 | D6: 46135 | E6: 上午 | F6: 因汐止建安店4/30轉換，故行程異動 | H6: 吳凱文 | I6: 店長
B7: 擔當 | C7: 市話 | D7: 變更日程 | H7: 依據版本 | L7: ##
A8: =IF(A6="","",LEFT(INDEX(店舖!$A:$L,MATCH(A6,店舖!$B:$B,),MATCH("店型",店舖!$1:$1,)),7)) -> RC | B8: =IF(A6="","",LEFT(INDEX(店舖!$A:$L,MATCH(A6,店舖!$B:$B,),MATCH("營業擔當姓名",店舖!$1:$1,)),5)) -> 王美瓔 | C8: =IF(B8="","",LEFT(INDEX(店舖!$A:$L,MATCH(A6,店舖!$B:$B,),MATCH("市話",店舖!$1:$1,)),10)) -> 02-7709213 | D8: 46142 | E8: 下午 | H8: 04-1150406 | L8: =IFERROR(INDEX(擔當公務機!A:B,MATCH(B8,擔當公務機!A:A,0),2),"") -> 0979204810
A9: 2
A10: 店 號 | B10: 店 名 | C10: 網路電話 | D10: 原訂日程 | F10: 異動原由 | H10: 通知人員 | I10: 確認人
B11: =IF(A11="","",LEFT(INDEX(店舖!$A:$L,MATCH(A11,店舖!$B:$B,),MATCH("店名",店舖!$1:$1,)),5)) | C11: =IF(B11="","",LEFT(INDEX(店舖!$A:$L,MATCH(A11,店舖!$B:$B,),MATCH("電話",店舖!$1:$1,)),10)) | N11: 0
B12: 擔當 | C12: 市話 | D12: 變更日程 | H12: 依據版本 | L12: ##
A13: =IF(A11="","",LEFT(INDEX(店舖!$A:$L,MATCH(A11,店舖!$B:$B,),MATCH("店型",店舖!$1:$1,)),5)) | B13: =IF(A11="","",LEFT(INDEX(店舖!$A:$L,MATCH(A11,店舖!$B:$B,),MATCH("營業擔當姓名",店舖!$1:$1,)),5)) | C13: =IF(B13="","",LEFT(INDEX(店舖!$A:$L,MATCH(A11,店舖!$B:$B,),MATCH("市話",店舖!$1:$1,)),10)) | H13: =H8 -> 04-1150406 | L13: =IFERROR(INDEX(擔當公務機!A:B,MATCH(B13,擔當公務機!A:A,0),2),"")
A14: 3
A15: 店 號 | B15: 店 名 | C15: 網路電話 | D15: 原訂日程 | F15: 異動原由 | H15: 通知人員 | I15: 確認人
B16: =IF(A16="","",LEFT(INDEX(店舖!$A:$L,MATCH(A16,店舖!$B:$B,),MATCH("店名",店舖!$1:$1,)),5)) | C16: =IF(B16="","",LEFT(INDEX(店舖!$A:$L,MATCH(A16,店舖!$B:$B,),MATCH("電話",店舖!$1:$1,)),10))
B17: 擔當 | C17: 市話 | D17: 變更日程 | H17: 依據版本 | L17: ##
A18: =IF(A16="","",LEFT(INDEX(店舖!$A:$L,MATCH(A16,店舖!$B:$B,),MATCH("店型",店舖!$1:$1,)),5)) | B18: =IF(A16="","",LEFT(INDEX(店舖!$A:$L,MATCH(A16,店舖!$B:$B,),MATCH("營業擔當姓名",店舖!$1:$1,)),5)) | C18: =IF(B18="","",LEFT(INDEX(店舖!$A:$L,MATCH(A16,店舖!$B:$B,),MATCH("市話",店舖!$1:$1,)),10)) | H18: =H13 -> 04-1150406 | L18: =IFERROR(INDEX(擔當公務機!A:B,MATCH(B18,擔當公務機!A:A,0),2),"")
A19: 4
A20: 店 號 | B20: 店 名 | C20: 網路電話 | D20: 原訂日程 | F20: 異動原由 | H20: 通知人員 | I20: 確認人
B21: =IF(A21="","",LEFT(INDEX(店舖!$A:$L,MATCH(A21,店舖!$B:$B,),MATCH("店名",店舖!$1:$1,)),5)) | C21: =IF(B21="","",LEFT(INDEX(店舖!$A:$L,MATCH(A21,店舖!$B:$B,),MATCH("電話",店舖!$1:$1,)),10))
B22: 擔當 | C22: 市話 | D22: 變更日程 | H22: 依據版本 | L22: ##
A23: =IF(A21="","",LEFT(INDEX(店舖!$A:$L,MATCH(A21,店舖!$B:$B,),MATCH("店型",店舖!$1:$1,)),5)) | B23: =IF(A21="","",LEFT(INDEX(店舖!$A:$L,MATCH(A21,店舖!$B:$B,),MATCH("營業擔當姓名",店舖!$1:$1,)),5)) | C23: =IF(B23="","",LEFT(INDEX(店舖!$A:$L,MATCH(A21,店舖!$B:$B,),MATCH("市話",店舖!$1:$1,)),10)) | H23: =H18 -> 04-1150406 | L23: =IFERROR(INDEX(擔當公務機!A:B,MATCH(B23,擔當公務機!A:A,0),2),"")
A24: 5
A25: 店 號 | B25: 店 名 | C25: 網路電話 | D25: 原訂日程 | F25: 異動原由 | H25: 通知人員 | I25: 確認人
B26: =IF(A26="","",LEFT(INDEX(店舖!$A:$L,MATCH(A26,店舖!$B:$B,),MATCH("店名",店舖!$1:$1,)),5)) | C26: =IF(B26="","",LEFT(INDEX(店舖!$A:$L,MATCH(A26,店舖!$B:$B,),MATCH("電話",店舖!$1:$1,)),10))
B27: 擔當 | C27: 市話 | D27: 變更日程 | H27: 依據版本 | L27: ##
A28: =IF(A26="","",LEFT(INDEX(店舖!$A:$L,MATCH(A26,店舖!$B:$B,),MATCH("店型",店舖!$1:$1,)),5)) | B28: =IF(A26="","",LEFT(INDEX(店舖!$A:$L,MATCH(A26,店舖!$B:$B,),MATCH("營業擔當姓名",店舖!$1:$1,)),5)) | C28: =IF(B28="","",LEFT(INDEX(店舖!$A:$L,MATCH(A26,店舖!$B:$B,),MATCH("市話",店舖!$1:$1,)),10)) | H28: =H23 -> 04-1150406 | L28: =IFERROR(INDEX(擔當公務機!A:B,MATCH(B28,擔當公務機!A:A,0),2),"")
A29: 6
A30: 店 號 | B30: 店 名 | C30: 網路電話 | D30: 原訂日程 | F30: 異動原由 | H30: 通知人員 | I30: 確認人
B31: =IF(A31="","",LEFT(INDEX(店舖!$A:$L,MATCH(A31,店舖!$B:$B,),MATCH("店名",店舖!$1:$1,)),5)) | C31: =IF(B31="","",LEFT(INDEX(店舖!$A:$L,MATCH(A31,店舖!$B:$B,),MATCH("電話",店舖!$1:$1,)),10))
B32: 擔當 | C32: 市話 | D32: 變更日程 | H32: 依據版本 | L32: ##
A33: =IF(A31="","",LEFT(INDEX(店舖!$A:$L,MATCH(A31,店舖!$B:$B,),MATCH("店型",店舖!$1:$1,)),5)) | B33: =IF(A31="","",LEFT(INDEX(店舖!$A:$L,MATCH(A31,店舖!$B:$B,),MATCH("營業擔當姓名",店舖!$1:$1,)),5)) | C33: =IF(B33="","",LEFT(INDEX(店舖!$A:$L,MATCH(A31,店舖!$B:$B,),MATCH("市話",店舖!$1:$1,)),10)) | H33: =H28 -> 04-1150406 | L33: =IFERROR(INDEX(擔當公務機!A:B,MATCH(B33,擔當公務機!A:A,0),2),"")
A34: 7
A35: 店 號 | B35: 店 名 | C35: 網路電話 | D35: 原訂日程 | F35: 異動原由 | H35: 通知人員 | I35: 確認人
B36: =IF(A36="","",LEFT(INDEX(店舖!$A:$L,MATCH(A36,店舖!$B:$B,),MATCH("店名",店舖!$1:$1,)),5)) | C36: =IF(B36="","",LEFT(INDEX(店舖!$A:$L,MATCH(A36,店舖!$B:$B,),MATCH("電話",店舖!$1:$1,)),10))
B37: 擔當 | C37: 市話 | D37: 變更日程 | H37: 依據版本 | L37: ##
A38: =IF(A36="","",LEFT(INDEX(店舖!$A:$L,MATCH(A36,店舖!$B:$B,),MATCH("店型",店舖!$1:$1,)),5)) | B38: =IF(A36="","",LEFT(INDEX(店舖!$A:$L,MATCH(A36,店舖!$B:$B,),MATCH("營業擔當姓名",店舖!$1:$1,)),5)) | C38: =IF(B38="","",LEFT(INDEX(店舖!$A:$L,MATCH(A36,店舖!$B:$B,),MATCH("市話",店舖!$1:$1,)),10)) | H38: =H33 -> 04-1150406 | L38: =IFERROR(INDEX(擔當公務機!A:B,MATCH(B38,擔當公務機!A:A,0),2),"")
A39: 8
A40: 店 號 | B40: 店 名 | C40: 網路電話 | D40: 原訂日程 | F40: 異動原由 | H40: 通知人員 | I40: 確認人
B41: =IF(A41="","",LEFT(INDEX(店舖!$A:$L,MATCH(A41,店舖!$B:$B,),MATCH("店名",店舖!$1:$1,)),5)) | C41: =IF(B41="","",LEFT(INDEX(店舖!$A:$L,MATCH(A41,店舖!$B:$B,),MATCH("電話",店舖!$1:$1,)),10))
...

Sheet 盤點行程變更通知書
B2: 盤點行程變更通知書-1
A4: ( | B4: =行程異動連絡單!B6 -> 汐止新樹店 | C4: ) 店長您好！
B6: 貴店原訂 | C6: =行程異動連絡單!D6 -> 46135 | D6: =WEEKDAY(C6,1) -> 5 | E6: =行程異動連絡單!E6 -> 上午 | G6: 實施盤點﹐
B8: 茲因本課為配合突發性質之業務需要﹐特將貴店原排定之
B10: 盤點日調整為 | C10: =行程異動連絡單!D8 -> 46142 | D10: =WEEKDAY(C10,1) -> 5 | E10: =行程異動連絡單!E8 -> 下午 | G10: 實施
E16: 全家便利商店
E17: 財會部
E19: =NOW() -> 46124.966
B21: 盤點行程變更通知書-2
A23: ( | B23: =行程異動連絡單!B11 | C23: ) 店長您好！
B25: 貴店原訂 | C25: =行程異動連絡單!D11 -> 0 | D25: =WEEKDAY(C25,1) -> 7 | E25: =行程異動連絡單!E11 -> 0 | G25: 實施盤點﹐
B27: 茲因本課為配合突發性質之業務需要﹐特將貴店原排定之
B29: 盤點日調整為 | C29: =行程異動連絡單!D13 -> 0 | D29: =WEEKDAY(C29,1) -> 7 | E29: =行程異動連絡單!E13 -> 0 | G29: 實施
E35: 全家便利商店
E36: 財會部
E38: =NOW() -> 46124.966
B40: 盤點行程變更通知書-3
A42: ( | B42: =行程異動連絡單!B16 | C42: ) 店長您好！
B44: 貴店原訂 | C44: =行程異動連絡單!D16 -> 0 | D44: =WEEKDAY(C44,1) -> 7 | E44: =行程異動連絡單!E16 -> 0 | G44: 實施盤點﹐
B46: 茲因本課為配合突發性質之業務需要﹐特將貴店原排定之
B48: 盤點日調整為 | C48: =行程異動連絡單!D18 -> 0 | D48: =WEEKDAY(C48,1) -> 7 | E48: =行程異動連絡單!E18 -> 0 | G48: 實施
E54: 全家便利商店
E55: 財會部
E57: =NOW() -> 46124.966
B59: 盤點行程變更通知書-4
A61: ( | B61: =行程異動連絡單!B21 | C61: ) 店長您好！
B63: 貴店原訂 | C63: =行程異動連絡單!D21 -> 0 | D63: =WEEKDAY(C63,1) -> 7 | E63: =行程異動連絡單!E21 -> 0 | G63: 實施盤點﹐
B65: 茲因本課為配合突發性質之業務需要﹐特將貴店原排定之
B67: 盤點日調整為 | C67: =行程異動連絡單!D23 -> 0 | D67: =WEEKDAY(C67,1) -> 7 | E67: =行程異動連絡單!E23 -> 0 | G67: 實施
E73: 全家便利商店
E74: 財會部
E76: =NOW() -> 46124.966
B78: 盤點行程變更通知書-5
A80: ( | B80: =行程異動連絡單!B26 | C80: ) 店長您好！
B82: 貴店原訂 | C82: =行程異動連絡單!D26 -> 0 | D82: =WEEKDAY(C82,1) -> 7 | E82: =行程異動連絡單!E26 -> 0 | G82: 實施盤點﹐
B84: 茲因本課為配合突發性質之業務需要﹐特將貴店原排定之
B86: 盤點日調整為 | C86: =行程異動連絡單!D28 -> 0 | D86: =WEEKDAY(C86,1) -> 7 | E86: =行程異動連絡單!E28 -> 0 | G86: 實施
E92: 全家便利商店
E93: 財會部
E95: =NOW() -> 46124.966
...

Sheet 店舖
B1: 店號 | C1: 店名 | D1: 店型 | E1: 營業擔當姓名 | F1: 電話 | G1: 市話 | H1: 擔當電話
B2: 015563 | C2: 七堵大興店 | D2: FC | E2: 簡若安 | F2: 02-77230557 | G2: 02-77230557 | H2: 02-24560059
B3: 017681 | C3: 七堵工明店 | D3: FC | E3: 連品聿 | F3: 02-77230551 | G3: 02-77230551 | H3: 02-24519520 | I3: 46113
B4: 022013 | C4: 七堵永富店 | D4: FC | E4: 連品聿 | F4: 02-77230552 | G4: 02-77230552 | H4: 02-24558170
B5: 019672 | C5: 七堵自治店 | D5: FC | E5: 連品聿 | F5: 02-77337902 | G5: 02-77337902 | H5: 02-24554377
B6: 025203 | C6: 七堵東新店 | D6: FC | E6: 連品聿 | F6: 02-77510019 | G6: 02-77510019 | H6: 02-27678206
B7: 023592 | C7: 七堵長安店 | D7: FC | E7: 連品聿 | F7: 02-77136820 | G7: 02-77136820 | H7: 02-24519266
B8: 023003 | C8: 七堵泰安店 | D8: FC | E8: 簡若安 | F8: 02- | G8: 02- | H8: 02-24519733
B9: 017207 | C9: 七堵新明德店 | D9: FC | E9: 連品聿 | F9: 02-77230556 | G9: 02-77230556 | H9: 02-24517467
B10: 024063 | C10: 九份觀景店 | D10: FC | E10: 游思敏 | F10: 02-77462348 | G10: 02-77462348 | H10: 02-24969045
B11: 023727 | C11: 九如東寧店 | D11: FC | E11: 王鳳鳴 | F11: 08-8218630 | G11: 08-8218630 | H11: 08-7397995
B12: 018286 | C12: 二林斗苑店 | D12: FC | E12: 許嘉恩 | F12: 04-7062279 | G12: 04-7062279 | H12: 04-8955612
B13: 024996 | C13: 二林矽品店 | D13: FC | E13: 陳建元 | F13: 04- | G13: 04- | H13: 04-7535127
B14: 023375 | C14: 二林原斗店 | D14: FC | E14: 張名翔 | F14: 04-7060109 | G14: 04-7060109 | H14: 04-8901566
B15: 023207 | C15: 二林路上店 | D15: FC | E15: 許嘉恩 | F15: 04- | G15: 04- | H15: 04-8966531
... B4484: 025410 | C4484: 鑫豐店 | D4484: RC | E4484: 謝金蓮 | F4484: - | G4484: 02-77462067 | H4484: 02-25157030
F4485: - | G4485: -
F4486: - | G4486: -
F4487: - | G4487: -
F4488: - | G4488: -
F4489: - | G4489: -
F4490: - | G4490: -
F4491: - | G4491: -
F4492: - | G4492: -
F4493: - | G4493: -
F4494: - | G4494: -
F4495: - | G4495: -
F4496: - | G4496: -
... F4549: - | G4549: -

Sheet 擔當公務機
A1: 姓 | B1: 電
A2: 吳駿銘 | B2: 0958353918
A3: 鄭猛夫 | B3: 0958771320
A4: 連品聿 | B4: 0937872777
A5: 陳姵甄 | B5: 0917889239
A6: 李貞慧 | B6: 0921693116
A7: 鄭佳銘 | B7: 0976885516
A8: 吳靜影 | B8: 0987227199
A9: 許竣嘉 | B9: 0970032571
A10: 鄭晏婷 | B10: 0912679375
A11: 游思敏 | B11: 0931116851
A12: 傅文衡 | B12: 0972867170
... A615: 吳毓文 | B615: 0909290912
